Signature: AttributeError: 'list' object has no attribute 'decode' (file "/home/paul/workspace/sopel/sopenv/lib/python2.7/site-packages/sopel/bot.py", line 300, in say)
from pew at 2016-09-18 00:44:06.095941. Message was: .vtbash 2 4 5 3
Traceback (most recent call last):
  File "/home/paul/workspace/sopel/sopenv/lib/python2.7/site-packages/sopel/bot.py", line 465, in call
    exit_code = func(sopel, trigger)
  File "/home/paul/.sopel/modules/vtbash.py", line 6, in vtbash
    bot.say(args)
  File "/home/paul/workspace/sopel/sopenv/lib/python2.7/site-packages/sopel/bot.py", line 402, in say
    self._bot.say(message, destination, max_messages)
  File "/home/paul/workspace/sopel/sopenv/lib/python2.7/site-packages/sopel/bot.py", line 300, in say
    text = encoded_text.decode('utf-8')
AttributeError: 'list' object has no attribute 'decode'
----------------------------------------

Signature: KeyError: u'chanlog_locks' (file "/home/paul/.sopel/modules/log.py", line 23, in log_everything)
from pew at 2016-09-18 01:35:01.977283. Message was: 
Traceback (most recent call last):
  File "/home/paul/workspace/sopel/sopenv/lib/python2.7/site-packages/sopel/bot.py", line 465, in call
    exit_code = func(sopel, trigger)
  File "/home/paul/.sopel/modules/log.py", line 23, in log_everything
    with bot.memory['chanlog_locks'][fpath]:
KeyError: u'chanlog_locks'
----------------------------------------

Signature: KeyError: u'chanlog_locks' (file "/home/paul/.sopel/modules/log.py", line 23, in log_everything)
from pew at 2016-09-18 01:36:38.578962. Message was: 
Traceback (most recent call last):
  File "/home/paul/workspace/sopel/sopenv/lib/python2.7/site-packages/sopel/bot.py", line 465, in call
    exit_code = func(sopel, trigger)
  File "/home/paul/.sopel/modules/log.py", line 23, in log_everything
    with bot.memory['chanlog_locks'][fpath]:
KeyError: u'chanlog_locks'
----------------------------------------

Signature: KeyError: u'chanlog_locks' (file "/home/paul/.sopel/modules/log.py", line 23, in log_everything)
from pew at 2016-09-18 01:40:03.648952. Message was: 
Traceback (most recent call last):
  File "/home/paul/workspace/sopel/sopenv/lib/python2.7/site-packages/sopel/bot.py", line 465, in call
    exit_code = func(sopel, trigger)
  File "/home/paul/.sopel/modules/log.py", line 23, in log_everything
    with bot.memory['chanlog_locks'][fpath]:
KeyError: u'chanlog_locks'
----------------------------------------

Signature: AttributeError: __exit__ (file "/home/paul/.sopel/modules/log.py", line 23, in log_everything)
from pew at 2016-09-18 01:42:11.295972. Message was: 
Traceback (most recent call last):
  File "/home/paul/workspace/sopel/sopenv/lib/python2.7/site-packages/sopel/bot.py", line 465, in call
    exit_code = func(sopel, trigger)
  File "/home/paul/.sopel/modules/log.py", line 23, in log_everything
    with [fpath]:
AttributeError: __exit__
----------------------------------------

Signature: KeyError: u'chanlog_locks' (file "/home/paul/.sopel/modules/log.py", line 24, in log_everything)
from pew at 2016-09-18 01:45:51.788904. Message was: 
Traceback (most recent call last):
  File "/home/paul/workspace/sopel/sopenv/lib/python2.7/site-packages/sopel/bot.py", line 465, in call
    exit_code = func(sopel, trigger)
  File "/home/paul/.sopel/modules/log.py", line 24, in log_everything
    with bot.memory['chanlog_locks'][fpath]:
KeyError: u'chanlog_locks'
----------------------------------------

Signature: KeyError: u'chanlog_locks' (file "/home/paul/.sopel/modules/log.py", line 24, in log_everything)
from pew at 2016-09-18 01:47:58.497716. Message was: 
Traceback (most recent call last):
  File "/home/paul/workspace/sopel/sopenv/lib/python2.7/site-packages/sopel/bot.py", line 465, in call
    exit_code = func(sopel, trigger)
  File "/home/paul/.sopel/modules/log.py", line 24, in log_everything
    with bot.memory['chanlog_locks'][fpath]:
KeyError: u'chanlog_locks'
----------------------------------------

Signature: NameError: global name 'datetime' is not defined (file "/home/paul/.sopel/modules/log.py", line 22, in log_everything)
from pew at 2016-09-18 01:54:15.173003. Message was: 
Traceback (most recent call last):
  File "/home/paul/workspace/sopel/sopenv/lib/python2.7/site-packages/sopel/bot.py", line 465, in call
    exit_code = func(sopel, trigger)
  File "/home/paul/.sopel/modules/log.py", line 22, in log_everything
    message = ''.join([datetime.utcnow(), trigger.nick, trigger, "\n"])
NameError: global name 'datetime' is not defined
----------------------------------------

Signature: TypeError: sequence item 0: expected string or Unicode, datetime.datetime found (file "/home/paul/.sopel/modules/log.py", line 23, in log_everything)
from pew at 2016-09-18 01:55:23.654273. Message was: 
Traceback (most recent call last):
  File "/home/paul/workspace/sopel/sopenv/lib/python2.7/site-packages/sopel/bot.py", line 465, in call
    exit_code = func(sopel, trigger)
  File "/home/paul/.sopel/modules/log.py", line 23, in log_everything
    message = ''.join([datetime.utcnow(), trigger.nick, trigger, "\n"])
TypeError: sequence item 0: expected string or Unicode, datetime.datetime found
----------------------------------------

Signature: KeyError: u'chanlog_locks' (file "/home/paul/.sopel/modules/log.py", line 31, in log_everything)
from pew at 2016-09-18 02:09:05.092229. Message was: 
Traceback (most recent call last):
  File "/home/paul/workspace/sopel/sopenv/lib/python2.7/site-packages/sopel/bot.py", line 465, in call
    exit_code = func(sopel, trigger)
  File "/home/paul/.sopel/modules/log.py", line 31, in log_everything
    with bot.memory['chanlog_locks'][fpath]:
KeyError: u'chanlog_locks'
----------------------------------------

Signature: KeyError: u'chanlog_locks' (file "/home/paul/.sopel/modules/log.py", line 31, in log_everything)
from pew at 2016-09-18 02:10:23.083623. Message was: 
Traceback (most recent call last):
  File "/home/paul/workspace/sopel/sopenv/lib/python2.7/site-packages/sopel/bot.py", line 465, in call
    exit_code = func(sopel, trigger)
  File "/home/paul/.sopel/modules/log.py", line 31, in log_everything
    with bot.memory['chanlog_locks'][fpath]:
KeyError: u'chanlog_locks'
----------------------------------------

